<?xml version="1.0" ?>
<!-- =================================================================================== -->
<!-- |    This document was autogenerated by xacro from tom_full.urdf.xacro            | -->
<!-- |    EDITING THIS FILE BY HAND IS NOT RECOMMENDED                                 | -->
<!-- =================================================================================== -->
<!--

	Author: Emmanuel Dean dean@tum.de
  
  This work is licensed under the Creative Commons Attribution-NonCommercial-NoDerivs 3.0 Unported License.
  To view a copy of this license, visit http://creativecommons.org/licenses/by-nc-nd/3.0/ or send a letter to
  Creative Commons, 444 Castro Street, Suite 900, Mountain View, California, 94041, USA.
-->
<robot name="tom" xmlns:controller="http://playerstage.sourceforge.net/gazebo/xmlschema/#controller" xmlns:interface="http://playerstage.sourceforge.net/gazebo/xmlschema/#interface" xmlns:sensor="http://playerstage.sourceforge.net/gazebo/xmlschema/#sensor" xmlns:xacro="http://www.ros.org/wiki/xacro">
  <!--Common definitions -->
  <!--Base Parameters -->
  <!-- xacro macros Base -->
  <!--Common definitions -->
  <!--Base Parameters -->
  <!-- xacro macros Wheels-->
  <!-- xacro base (includes: base, Logos, Torso, wheels) -->
  <!-- xacro macros Sensors -->
  <!--Common definitions -->
  <!--Base Parameters -->
  <!-- xacro sensors  -->
  <!--xacro macros Arms-->
  <!--xacro:include filename="$(find tom_description)/urdf/arm/ur5/ur5.urdf.xacro"/-->
  <!--Common definitions -->
  <!--Base Parameters -->
  <!-- Hand specializations -->
  <!--xacro macros Arms-->
  <!-- Inertia parameters -->
  <!-- This mass might be incorrect -->
  <!-- Kinematic model -->
  <!-- Properties from urcontrol.conf -->
  <!--
    DH for UR5:
    a = [0.00000, -0.42500, -0.39225,  0.00000,  0.00000,  0.0000]
    d = [0.089159,  0.00000,  0.00000,  0.10915,  0.09465,  0.0823]
    alpha = [ 1.570796327, 0, 0, 1.570796327, -1.570796327, 0 ]
    q_home_offset = [0, -1.570796327, 0, -1.570796327, 0, 0]
    joint_direction = [-1, -1, 1, 1, 1, 1]
    mass = [3.7000, 8.3930, 2.2750, 1.2190, 1.2190, 0.1879]
    center_of_mass = [ [0, -0.02561, 0.00193], [0.2125, 0, 0.11336], [0.11993, 0.0, 0.0265], [0, -0.0018, 0.01634], [0, 0.0018,0.01634], [0, 0, -0.001159] ]
  -->
  <!-- Arbitrary offsets for shoulder/elbow joints -->
  <!-- measured from model -->
  <!-- measured from model -->
  <!-- link lengths used in model -->
  <!--property name="shoulder_height" value="0.089159" /-->
  <!--property name="shoulder_offset" value="0.13585" /-->
  <!-- shoulder_offset - elbow_offset + wrist_1_length = 0.10915 -->
  <!--property name="upper_arm_length" value="0.42500" /-->
  <!--property name="elbow_offset" value="0.1197" /-->
  <!-- CAD measured -->
  <!--property name="forearm_length" value="0.39225" /-->
  <!--property name="wrist_1_length" value="0.093" /-->
  <!-- CAD measured -->
  <!--property name="wrist_2_length" value="0.09465" /-->
  <!-- In CAD this distance is 0.930, but in the spec it is 0.09465 -->
  <!--property name="wrist_3_length" value="0.0823" /-->
  <!-- manually measured -->
  <!-- manually measured -->
  <!-- manually measured -->
  <!-- manually measured -->
  <!-- manually measured -->
  <!-- xacro arms (right_arm=true -> right arm, false -> left arm -->
  <!--xacro macros Hands-->
  <!--Common definitions -->
  <!--Base Parameters -->
  <!-- Hand specializations -->
  <!-- ======================== BASE PARAMS ========================= -->
  <!-- ======================== FINGER PARAMS ======================== -->
  <!-- full height from joint to tip. when used,
the radius of the finger tip sphere will be subtracted
and one fixed link will be added for the tip. -->
  <!--0.0435,   0.044981-->
  <!--0.002298-->
  <!--0.002298-->
  <!-- ========================= THUMB PARAMS ========================= -->
  <!-- ========================= LIMITS ========================= -->
  <!-- =============== Macro ================= -->
  <!-- ============================================================================= -->
  <!-- ============================================================================= -->
  <!-- ============================================================================= -->
  <!-- THUMB MACRO -->
  <!-- END THUMB MACRO -->
  <!-- THREE FINGER MACRO -->
  <!-- [[END]] THREE FINGER MACRO -->
  <!-- ======================== BASE PARAMS ========================= -->
  <!-- ======================== FINGER PARAMS ======================== -->
  <!-- full height from joint to tip. when used,
the radius of the finger tip sphere will be subtracted
and one fixed link will be added for the tip. -->
  <!--0.0435,   0.044981-->
  <!--0.002298-->
  <!--0.002298-->
  <!-- ========================= THUMB PARAMS ========================= -->
  <!-- ========================= LIMITS ========================= -->
  <!-- =============== Macro ================= -->
  <!-- ============================================================================= -->
  <!-- ============================================================================= -->
  <!-- ============================================================================= -->
  <!-- THUMB MACRO -->
  <!-- END THUMB MACRO -->
  <!-- THREE FINGER MACRO -->
  <!-- [[END]] THREE FINGER MACRO -->
  <!-- xacro hands (right_hand=true -> right hand, false -> left hand -->
  <!-- robot base, includes base, torso, wheels and logos -->
  <!--virtual link used with gazebo physics engine-->
  <!-- base_footprint is a fictitious link(frame) that is on the ground right below base_link origin,
         navigation stack dedpends on this frame -->
  <link name="base_footprint">
    <visual>
      <origin rpy="0 0 0" xyz="0 0 0"/>
      <geometry>
        <box size="0.01 0.01 0.01"/>
      </geometry>
      <material name="White"/>
    </visual>
    <collision>
      <!-- -->
      <origin rpy="0 0 0" xyz="0 0 0"/>
      <geometry>
        <box size="0.001 0.001 0.001"/>
      </geometry>
    </collision>
  </link>
  <joint name="base_footprint_joint" type="fixed">
    <origin rpy="0 0 0" xyz="0 0 0.051"/>
    <child link="base_link"/>
    <parent link="base_footprint"/>
  </joint>
  <link name="base_link">
    <visual>
      <origin rpy="1.5707963259 0 1.5707963259" xyz="0 0 0"/>
      <geometry>
        <mesh filename="package://tom_description/meshes/base/item_profile.dae"/>
      </geometry>
    </visual>
    <collision>
      <geometry>
        <!--box size="${base_length + base_collision_offset} ${base_width + base_collision_offset} ${base_hight + base_collision_offset}"/-->
        <mesh filename="package://tom_description/meshes/base/item_profile.dae"/>
      </geometry>
      <origin rpy="1.5707963259 0 1.5707963259" xyz="0 0 0"/>
      <!--origin xyz="${-(base_length+base_collision_offset)/2.0+0.15} 0 ${-(base_hight + base_collision_offset)/2+0.1}" rpy="0 0 0"/-->
    </collision>
    <inertial>
      <mass value="10.0"/>
      <inertia ixx="0.0" ixy="0.0" ixz="0.0" iyy="0.0" iyz="0.0" izz="0.0"/>
    </inertial>
  </link>
  <link name="torso_link">
    <visual>
      <origin rpy="1.57 0 1.57" xyz="-0.01614 0 -0.76268"/>
      <geometry>
        <mesh filename="package://tom_description/meshes/base/green_parts.dae"/>
      </geometry>
    </visual>
    <collision>
      <geometry>
        <!--box size="${torso_length + torso_collision_offset} ${torso_width + torso_collision_offset} ${torso_hight + torso_collision_offset}"/-->
        <mesh filename="package://tom_description/meshes/base/green_parts.dae"/>
      </geometry>
      <origin rpy="1.57 0 1.57" xyz="-0.01614 0 -0.76268"/>
      <!--origin xyz="0.0 0 ${-(torso_hight + torso_collision_offset)/2+0.075}" rpy="0 0 0"/-->
    </collision>
    <inertial>
      <mass value="10"/>
      <inertia ixx="0.0" ixy="0.0" ixz="0.0" iyy="0.0" iyz="0.0" izz="0.0"/>
    </inertial>
  </link>
  <joint name="base_to_torso" type="fixed">
    <parent link="base_link"/>
    <child link="torso_link"/>
    <origin xyz="0.01614 0 0.76268"/>
  </joint>
  <!-- Wheels-->
  <link name="l_front_wheel_link">
    <visual>
      <geometry>
        <mesh filename="package://tom_description/meshes/wheels/wheels.dae"/>
      </geometry>
      <material name="white">
        <color rgba="1 1 1 1"/>
      </material>
    </visual>
    <collision>
      <origin rpy="0 0 0" xyz="0 0 0"/>
      <!-- rotation because cyl. geom primitive has symmetry axis in +x direction -->
      <geometry>
        <cylinder length="0.075" radius="0.1"/>
      </geometry>
    </collision>
    <inertial>
      <!--copy from pr2_description, we should use the real values-->
      <mass value="0.44036"/>
      <origin xyz="0 0 0"/>
      <inertia ixx="0.012411765597" ixy="-0.000711733678" ixz="0.00050272983" iyy="0.015218160428" iyz="-0.000004273467" izz="0.011763977943"/>
    </inertial>
  </link>
  <joint name="l_front_wheel_joint" type="continuous">
    <parent link="base_link"/>
    <child link="l_front_wheel_link"/>
    <origin rpy="-1.57 0 0" xyz="0 0.303 -0.40"/>
    <axis xyz="0 0 1"/>
  </joint>
  <link name="l_rear_wheel_link">
    <visual>
      <geometry>
        <mesh filename="package://tom_description/meshes/wheels/wheels.dae"/>
      </geometry>
      <material name="white">
        <color rgba="1 1 1 1"/>
      </material>
    </visual>
    <collision>
      <origin rpy="0 0 0" xyz="0 0 0"/>
      <!-- rotation because cyl. geom primitive has symmetry axis in +x direction -->
      <geometry>
        <cylinder length="0.075" radius="0.1"/>
      </geometry>
    </collision>
    <inertial>
      <!--copy from pr2_description, we should use the real values-->
      <mass value="0.44036"/>
      <origin xyz="0 0 0"/>
      <inertia ixx="0.012411765597" ixy="-0.000711733678" ixz="0.00050272983" iyy="0.015218160428" iyz="-0.000004273467" izz="0.011763977943"/>
    </inertial>
  </link>
  <joint name="l_rear_wheel_joint" type="continuous">
    <parent link="base_link"/>
    <child link="l_rear_wheel_link"/>
    <origin rpy="-1.57 0 0" xyz="-0.8115 0.303 -0.40"/>
    <axis xyz="0 0 1"/>
  </joint>
  <link name="r_front_wheel_link">
    <visual>
      <geometry>
        <mesh filename="package://tom_description/meshes/wheels/wheels.dae"/>
      </geometry>
      <material name="white">
        <color rgba="1 1 1 1"/>
      </material>
    </visual>
    <collision>
      <origin rpy="0 0 0" xyz="0 0 0"/>
      <!-- rotation because cyl. geom primitive has symmetry axis in +x direction -->
      <geometry>
        <cylinder length="0.075" radius="0.1"/>
      </geometry>
    </collision>
    <inertial>
      <!--copy from pr2_description, we should use the real values-->
      <mass value="0.44036"/>
      <origin xyz="0 0 0"/>
      <inertia ixx="0.012411765597" ixy="-0.000711733678" ixz="0.00050272983" iyy="0.015218160428" iyz="-0.000004273467" izz="0.011763977943"/>
    </inertial>
  </link>
  <joint name="r_front_wheel_joint" type="continuous">
    <parent link="base_link"/>
    <child link="r_front_wheel_link"/>
    <origin rpy="-1.57 0 0" xyz="0 -0.303 -0.40"/>
    <axis xyz="0 0 1"/>
  </joint>
  <link name="r_rear_wheel_link">
    <visual>
      <geometry>
        <mesh filename="package://tom_description/meshes/wheels/wheels.dae"/>
      </geometry>
      <material name="white">
        <color rgba="1 1 1 1"/>
      </material>
    </visual>
    <collision>
      <origin rpy="0 0 0" xyz="0 0 0"/>
      <!-- rotation because cyl. geom primitive has symmetry axis in +x direction -->
      <geometry>
        <cylinder length="0.075" radius="0.1"/>
      </geometry>
    </collision>
    <inertial>
      <!--copy from pr2_description, we should use the real values-->
      <mass value="0.44036"/>
      <origin xyz="0 0 0"/>
      <inertia ixx="0.012411765597" ixy="-0.000711733678" ixz="0.00050272983" iyy="0.015218160428" iyz="-0.000004273467" izz="0.011763977943"/>
    </inertial>
  </link>
  <joint name="r_rear_wheel_joint" type="continuous">
    <parent link="base_link"/>
    <child link="r_rear_wheel_link"/>
    <origin rpy="-1.57 0 0" xyz="-0.8115 -0.303 -0.40"/>
    <axis xyz="0 0 1"/>
  </joint>
  <!-- Deco Logos-->
  <link name="ICS_logo_blue_link">
    <visual>
      <origin rpy="1.57 0 1.57" xyz="0 0 0"/>
      <geometry>
        <mesh filename="package://tom_description/meshes/base/logo_blue.dae"/>
      </geometry>
    </visual>
    <collision>
      <origin rpy="1.57 0 1.57" xyz="0 0 0"/>
      <geometry>
        <mesh filename="package://tom_description/meshes/base/logo_blue.dae"/>
      </geometry>
    </collision>
  </link>
  <joint name="ICS_logo_blue" type="fixed">
    <parent link="base_link"/>
    <child link="ICS_logo_blue_link"/>
    <origin xyz="0 0 0"/>
  </joint>
  <link name="ICS_logo_grey_link">
    <visual>
      <origin rpy="1.57 0 1.57" xyz="0 0 0"/>
      <geometry>
        <mesh filename="package://tom_description/meshes/base/logo_grey.dae"/>
      </geometry>
    </visual>
    <collision>
      <origin rpy="1.57 0 1.57" xyz="0 0 0"/>
      <geometry>
        <mesh filename="package://tom_description/meshes/base/logo_grey.dae"/>
      </geometry>
    </collision>
  </link>
  <joint name="ICS_logo_grey" type="fixed">
    <parent link="base_link"/>
    <child link="ICS_logo_grey_link"/>
    <origin xyz="0 0 0"/>
  </joint>
  <!-- robot head, includes the left camera -->
  <link name="tom_left_camera_link">
    <visual>
      <origin rpy="0 0 0" xyz="0 0 0"/>
      <geometry>
        <box size="0.00 0.00 0.00"/>
      </geometry>
      <material name="orange">
        <color rgba="0.45 0.45 0.45 1.0"/>
      </material>
    </visual>
  </link>
  <link name="tom_head_link">
    <visual>
      <origin rpy="1.57079632679 0 -1.57079632679" xyz="1 1.255 -0.838"/>
      <geometry>
        <mesh filename="package://tom_description/meshes/head/head.stl" scale="0.001 0.001 0.001"/>
      </geometry>
      <material name="green">
        <color rgba="0.0 0.8 0.0 1"/>
      </material>
    </visual>
  </link>
  <joint name="table_head_joint" type="fixed">
    <origin rpy="0 0 0" xyz="0 0 0"/>
    <parent link="torso_link"/>
    <child link="tom_head_link"/>
  </joint>
  <joint name="tom_left_camera_joint" type="fixed">
    <origin rpy="-2.43606 -0.193804 -1.648299" xyz="0.075241 0.032279 0.211305"/>
    <parent link="torso_link"/>
    <child link="tom_left_camera_link"/>
  </joint>
  <!-- Arms -->
  <!-- Right Arm -->
  <!-- right UR5 robot model -->
  <link name="r_base_link">
    <visual>
      <geometry>
        <mesh filename="package://tom_description/meshes/arm/ur5/visual/Base.dae"/>
      </geometry>
      <material name="LightGrey">
        <color rgba="0.7 0.7 0.7 1.0"/>
      </material>
    </visual>
    <collision>
      <geometry>
        <mesh filename="package://tom_description/meshes/arm/ur5/collision/base.stl"/>
      </geometry>
    </collision>
    <inertial>
      <mass value="4.0"/>
      <origin rpy="0 0 0" xyz="0.0 0.0 0.0"/>
      <inertia ixx="0.00443333156" ixy="0.0" ixz="0.0" iyy="0.00443333156" iyz="0.0" izz="0.0072"/>
    </inertial>
  </link>
  <joint name="r_shoulder_pan_joint" type="revolute">
    <parent link="r_base_link"/>
    <child link="r_shoulder_link"/>
    <origin rpy="0.0 0.0 0.0" xyz="0.0 0.0 0.089159"/>
    <axis xyz="0 0 1"/>
    <limit effort="150.0" lower="-6.2831853" upper="6.2831853" velocity="3.15"/>
    <dynamics damping="0.0" friction="0.0"/>
  </joint>
  <link name="r_shoulder_link">
    <visual>
      <geometry>
        <mesh filename="package://tom_description/meshes/arm/ur5/visual/Shoulder.dae"/>
      </geometry>
      <material name="LightGrey">
        <color rgba="0.7 0.7 0.7 1.0"/>
      </material>
    </visual>
    <collision>
      <geometry>
        <mesh filename="package://tom_description/meshes/arm/ur5/collision/shoulder.stl"/>
      </geometry>
    </collision>
    <inertial>
      <mass value="3.7"/>
      <origin rpy="0 0 0" xyz="0.0 0.0 0.0"/>
      <inertia ixx="0.010267495893" ixy="0.0" ixz="0.0" iyy="0.010267495893" iyz="0.0" izz="0.00666"/>
    </inertial>
  </link>
  <joint name="r_shoulder_lift_joint" type="revolute">
    <parent link="r_shoulder_link"/>
    <child link="r_upper_arm_link"/>
    <origin rpy="0.0 1.570796325 0.0" xyz="0.0 0.13585 0.0"/>
    <axis xyz="0 1 0"/>
    <limit effort="150.0" lower="-6.2831853" upper="6.2831853" velocity="3.15"/>
    <dynamics damping="0.0" friction="0.0"/>
  </joint>
  <link name="r_upper_arm_link">
    <visual>
      <geometry>
        <mesh filename="package://tom_description/meshes/arm/ur5/visual/UpperArm.dae"/>
      </geometry>
      <material name="LightGrey">
        <color rgba="0.7 0.7 0.7 1.0"/>
      </material>
    </visual>
    <collision>
      <geometry>
        <mesh filename="package://tom_description/meshes/arm/ur5/collision/upper_arm.stl"/>
      </geometry>
    </collision>
    <inertial>
      <mass value="8.393"/>
      <origin rpy="0 0 0" xyz="0.0 0.0 0.28"/>
      <inertia ixx="0.22689067591" ixy="0.0" ixz="0.0" iyy="0.22689067591" iyz="0.0" izz="0.0151074"/>
    </inertial>
  </link>
  <joint name="r_elbow_joint" type="revolute">
    <parent link="r_upper_arm_link"/>
    <child link="r_forearm_link"/>
    <origin rpy="0.0 0.0 0.0" xyz="0.0 -0.1197 0.425"/>
    <axis xyz="0 1 0"/>
    <limit effort="150.0" lower="-6.2831853" upper="6.2831853" velocity="3.15"/>
    <dynamics damping="0.0" friction="0.0"/>
  </joint>
  <link name="r_forearm_link">
    <visual>
      <geometry>
        <mesh filename="package://tom_description/meshes/arm/ur5/visual/Forearm.dae"/>
      </geometry>
      <material name="LightGrey">
        <color rgba="0.7 0.7 0.7 1.0"/>
      </material>
    </visual>
    <collision>
      <geometry>
        <mesh filename="package://tom_description/meshes/arm/ur5/collision/forearm.stl"/>
      </geometry>
    </collision>
    <inertial>
      <mass value="2.275"/>
      <origin rpy="0 0 0" xyz="0.0 0.0 0.25"/>
      <inertia ixx="0.049443313556" ixy="0.0" ixz="0.0" iyy="0.049443313556" iyz="0.0" izz="0.004095"/>
    </inertial>
  </link>
  <joint name="r_wrist_1_joint" type="revolute">
    <parent link="r_forearm_link"/>
    <child link="r_wrist_1_link"/>
    <origin rpy="0.0 1.570796325 0.0" xyz="0.0 0.0 0.39225"/>
    <axis xyz="0 1 0"/>
    <limit effort="28.0" lower="-6.2831853" upper="6.2831853" velocity="3.2"/>
    <dynamics damping="0.0" friction="0.0"/>
  </joint>
  <link name="r_wrist_1_link">
    <visual>
      <geometry>
        <mesh filename="package://tom_description/meshes/arm/ur5/visual/Wrist1.dae"/>
      </geometry>
      <material name="LightGrey">
        <color rgba="0.7 0.7 0.7 1.0"/>
      </material>
    </visual>
    <collision>
      <geometry>
        <mesh filename="package://tom_description/meshes/arm/ur5/collision/wrist_1.stl"/>
      </geometry>
    </collision>
    <inertial>
      <mass value="1.219"/>
      <origin rpy="0 0 0" xyz="0.0 0.0 0.0"/>
      <inertia ixx="0.111172755531" ixy="0.0" ixz="0.0" iyy="0.111172755531" iyz="0.0" izz="0.21942"/>
    </inertial>
  </link>
  <joint name="r_wrist_2_joint" type="revolute">
    <parent link="r_wrist_1_link"/>
    <child link="r_wrist_2_link"/>
    <origin rpy="0.0 0.0 0.0" xyz="0.0 0.093 0.0"/>
    <axis xyz="0 0 1"/>
    <limit effort="28.0" lower="-6.2831853" upper="6.2831853" velocity="3.2"/>
    <dynamics damping="0.0" friction="0.0"/>
  </joint>
  <link name="r_wrist_2_link">
    <visual>
      <geometry>
        <mesh filename="package://tom_description/meshes/arm/ur5/visual/Wrist2.dae"/>
      </geometry>
      <material name="LightGrey">
        <color rgba="0.7 0.7 0.7 1.0"/>
      </material>
    </visual>
    <collision>
      <geometry>
        <mesh filename="package://tom_description/meshes/arm/ur5/collision/wrist_2.stl"/>
      </geometry>
    </collision>
    <inertial>
      <mass value="1.219"/>
      <origin rpy="0 0 0" xyz="0.0 0.0 0.0"/>
      <inertia ixx="0.111172755531" ixy="0.0" ixz="0.0" iyy="0.111172755531" iyz="0.0" izz="0.21942"/>
    </inertial>
  </link>
  <joint name="r_wrist_3_joint" type="revolute">
    <parent link="r_wrist_2_link"/>
    <child link="r_wrist_3_link"/>
    <origin rpy="0.0 0.0 0.0" xyz="0.0 0.0 0.09465"/>
    <axis xyz="0 1 0"/>
    <limit effort="28.0" lower="-6.2831853" upper="6.2831853" velocity="3.2"/>
    <dynamics damping="0.0" friction="0.0"/>
  </joint>
  <link name="r_wrist_3_link">
    <visual>
      <geometry>
        <mesh filename="package://tom_description/meshes/arm/ur5/visual/Wrist3.dae"/>
      </geometry>
      <material name="LightGrey">
        <color rgba="0.7 0.7 0.7 1.0"/>
      </material>
    </visual>
    <collision>
      <geometry>
        <mesh filename="package://tom_description/meshes/arm/ur5/collision/wrist_3.stl"/>
      </geometry>
    </collision>
    <inertial>
      <mass value="0.1879"/>
      <origin rpy="0 0 0" xyz="0.0 0.0 0.0"/>
      <inertia ixx="0.0171364731454" ixy="0.0" ixz="0.0" iyy="0.0171364731454" iyz="0.0" izz="0.033822"/>
    </inertial>
  </link>
  <joint name="r_ee_fixed_joint" type="fixed">
    <parent link="r_wrist_3_link"/>
    <child link="r_ee_link"/>
    <origin rpy="0.0 0.0 1.570796325" xyz="0.0 0.0823 0.0"/>
  </joint>
  <link name="r_ee_link">
    <collision>
      <geometry>
        <box size="0.01 0.01 0.01"/>
      </geometry>
      <origin rpy="0 0 0" xyz="-0.01 0 0"/>
    </collision>
  </link>
  <transmission name="r_shoulder_pan_trans">
    <type>transmission_interface/SimpleTransmission</type>
    <joint name="r_shoulder_pan_joint">
      <hardwareInterface>EffortJointInterface</hardwareInterface>
    </joint>
    <actuator name="r_shoulder_pan_motor">
      <mechanicalReduction>1</mechanicalReduction>
    </actuator>
  </transmission>
  <transmission name="r_shoulder_lift_trans">
    <type>transmission_interface/SimpleTransmission</type>
    <joint name="r_shoulder_lift_joint">
      <hardwareInterface>EffortJointInterface</hardwareInterface>
    </joint>
    <actuator name="r_shoulder_lift_motor">
      <mechanicalReduction>1</mechanicalReduction>
    </actuator>
  </transmission>
  <transmission name="r_elbow_trans">
    <type>transmission_interface/SimpleTransmission</type>
    <joint name="r_elbow_joint">
      <hardwareInterface>EffortJointInterface</hardwareInterface>
    </joint>
    <actuator name="r_elbow_motor">
      <mechanicalReduction>1</mechanicalReduction>
    </actuator>
  </transmission>
  <transmission name="r_wrist_1_trans">
    <type>transmission_interface/SimpleTransmission</type>
    <joint name="r_wrist_1_joint">
      <hardwareInterface>EffortJointInterface</hardwareInterface>
    </joint>
    <actuator name="r_wrist_1_motor">
      <mechanicalReduction>1</mechanicalReduction>
    </actuator>
  </transmission>
  <transmission name="r_wrist_2_trans">
    <type>transmission_interface/SimpleTransmission</type>
    <joint name="r_wrist_2_joint">
      <hardwareInterface>EffortJointInterface</hardwareInterface>
    </joint>
    <actuator name="r_wrist_2_motor">
      <mechanicalReduction>1</mechanicalReduction>
    </actuator>
  </transmission>
  <transmission name="r_wrist_3_trans">
    <type>transmission_interface/SimpleTransmission</type>
    <joint name="r_wrist_3_joint">
      <hardwareInterface>EffortJointInterface</hardwareInterface>
    </joint>
    <actuator name="r_wrist_3_motor">
      <mechanicalReduction>1</mechanicalReduction>
    </actuator>
  </transmission>
  <!-- nothing to do here at the moment -->
  <joint name="torso_to_r_arm" type="fixed">
    <parent link="torso_link"/>
    <child link="r_base_link"/>
    <origin rpy="2.6061 -0.6271 -0.5355" xyz="0 -0.225 0"/>
  </joint>
  <!-- This is the JR3 adapter -->
  <link name="r_hand_base_adapter_link">
    <visual>
      <origin rpy="1.57079632679 0 1.57079632679" xyz="0 0 -0.045"/>
      <geometry>
        <mesh filename="package://tom_description/meshes/arm/hand_mount.dae"/>
      </geometry>
    </visual>
    <collision>
      <origin rpy="0 0 0" xyz="0 0 -0.025"/>
      <geometry>
        <cylinder length="0.05" radius="0.035"/>
      </geometry>
    </collision>
  </link>
  <joint name="r_hand_base_adapter_joint" type="fixed">
    <parent link="r_ee_link"/>
    <child link="r_hand_base_adapter_link"/>
    <origin rpy="1.57079632679 2.356 1.57079632679" xyz="0.045 0 0"/>
  </joint>
  <!-- Left Arm -->
  <!-- left UR5 robot model -->
  <link name="l_base_link">
    <visual>
      <geometry>
        <mesh filename="package://tom_description/meshes/arm/ur5/visual/Base.dae"/>
      </geometry>
      <material name="LightGrey">
        <color rgba="0.7 0.7 0.7 1.0"/>
      </material>
    </visual>
    <collision>
      <geometry>
        <mesh filename="package://tom_description/meshes/arm/ur5/collision/base.stl"/>
      </geometry>
    </collision>
    <inertial>
      <mass value="4.0"/>
      <origin rpy="0 0 0" xyz="0.0 0.0 0.0"/>
      <inertia ixx="0.00443333156" ixy="0.0" ixz="0.0" iyy="0.00443333156" iyz="0.0" izz="0.0072"/>
    </inertial>
  </link>
  <joint name="l_shoulder_pan_joint" type="revolute">
    <parent link="l_base_link"/>
    <child link="l_shoulder_link"/>
    <origin rpy="0.0 0.0 0.0" xyz="0.0 0.0 0.089159"/>
    <axis xyz="0 0 1"/>
    <limit effort="150.0" lower="-6.2831853" upper="6.2831853" velocity="3.15"/>
    <dynamics damping="0.0" friction="0.0"/>
  </joint>
  <link name="l_shoulder_link">
    <visual>
      <geometry>
        <mesh filename="package://tom_description/meshes/arm/ur5/visual/Shoulder.dae"/>
      </geometry>
      <material name="LightGrey">
        <color rgba="0.7 0.7 0.7 1.0"/>
      </material>
    </visual>
    <collision>
      <geometry>
        <mesh filename="package://tom_description/meshes/arm/ur5/collision/shoulder.stl"/>
      </geometry>
    </collision>
    <inertial>
      <mass value="3.7"/>
      <origin rpy="0 0 0" xyz="0.0 0.0 0.0"/>
      <inertia ixx="0.010267495893" ixy="0.0" ixz="0.0" iyy="0.010267495893" iyz="0.0" izz="0.00666"/>
    </inertial>
  </link>
  <joint name="l_shoulder_lift_joint" type="revolute">
    <parent link="l_shoulder_link"/>
    <child link="l_upper_arm_link"/>
    <origin rpy="0.0 1.570796325 0.0" xyz="0.0 0.13585 0.0"/>
    <axis xyz="0 1 0"/>
    <limit effort="150.0" lower="-6.2831853" upper="6.2831853" velocity="3.15"/>
    <dynamics damping="0.0" friction="0.0"/>
  </joint>
  <link name="l_upper_arm_link">
    <visual>
      <geometry>
        <mesh filename="package://tom_description/meshes/arm/ur5/visual/UpperArm.dae"/>
      </geometry>
      <material name="LightGrey">
        <color rgba="0.7 0.7 0.7 1.0"/>
      </material>
    </visual>
    <collision>
      <geometry>
        <mesh filename="package://tom_description/meshes/arm/ur5/collision/upper_arm.stl"/>
      </geometry>
    </collision>
    <inertial>
      <mass value="8.393"/>
      <origin rpy="0 0 0" xyz="0.0 0.0 0.28"/>
      <inertia ixx="0.22689067591" ixy="0.0" ixz="0.0" iyy="0.22689067591" iyz="0.0" izz="0.0151074"/>
    </inertial>
  </link>
  <joint name="l_elbow_joint" type="revolute">
    <parent link="l_upper_arm_link"/>
    <child link="l_forearm_link"/>
    <origin rpy="0.0 0.0 0.0" xyz="0.0 -0.1197 0.425"/>
    <axis xyz="0 1 0"/>
    <limit effort="150.0" lower="-6.2831853" upper="6.2831853" velocity="3.15"/>
    <dynamics damping="0.0" friction="0.0"/>
  </joint>
  <link name="l_forearm_link">
    <visual>
      <geometry>
        <mesh filename="package://tom_description/meshes/arm/ur5/visual/Forearm.dae"/>
      </geometry>
      <material name="LightGrey">
        <color rgba="0.7 0.7 0.7 1.0"/>
      </material>
    </visual>
    <collision>
      <geometry>
        <mesh filename="package://tom_description/meshes/arm/ur5/collision/forearm.stl"/>
      </geometry>
    </collision>
    <inertial>
      <mass value="2.275"/>
      <origin rpy="0 0 0" xyz="0.0 0.0 0.25"/>
      <inertia ixx="0.049443313556" ixy="0.0" ixz="0.0" iyy="0.049443313556" iyz="0.0" izz="0.004095"/>
    </inertial>
  </link>
  <joint name="l_wrist_1_joint" type="revolute">
    <parent link="l_forearm_link"/>
    <child link="l_wrist_1_link"/>
    <origin rpy="0.0 1.570796325 0.0" xyz="0.0 0.0 0.39225"/>
    <axis xyz="0 1 0"/>
    <limit effort="28.0" lower="-6.2831853" upper="6.2831853" velocity="3.2"/>
    <dynamics damping="0.0" friction="0.0"/>
  </joint>
  <link name="l_wrist_1_link">
    <visual>
      <geometry>
        <mesh filename="package://tom_description/meshes/arm/ur5/visual/Wrist1.dae"/>
      </geometry>
      <material name="LightGrey">
        <color rgba="0.7 0.7 0.7 1.0"/>
      </material>
    </visual>
    <collision>
      <geometry>
        <mesh filename="package://tom_description/meshes/arm/ur5/collision/wrist_1.stl"/>
      </geometry>
    </collision>
    <inertial>
      <mass value="1.219"/>
      <origin rpy="0 0 0" xyz="0.0 0.0 0.0"/>
      <inertia ixx="0.111172755531" ixy="0.0" ixz="0.0" iyy="0.111172755531" iyz="0.0" izz="0.21942"/>
    </inertial>
  </link>
  <joint name="l_wrist_2_joint" type="revolute">
    <parent link="l_wrist_1_link"/>
    <child link="l_wrist_2_link"/>
    <origin rpy="0.0 0.0 0.0" xyz="0.0 0.093 0.0"/>
    <axis xyz="0 0 1"/>
    <limit effort="28.0" lower="-6.2831853" upper="6.2831853" velocity="3.2"/>
    <dynamics damping="0.0" friction="0.0"/>
  </joint>
  <link name="l_wrist_2_link">
    <visual>
      <geometry>
        <mesh filename="package://tom_description/meshes/arm/ur5/visual/Wrist2.dae"/>
      </geometry>
      <material name="LightGrey">
        <color rgba="0.7 0.7 0.7 1.0"/>
      </material>
    </visual>
    <collision>
      <geometry>
        <mesh filename="package://tom_description/meshes/arm/ur5/collision/wrist_2.stl"/>
      </geometry>
    </collision>
    <inertial>
      <mass value="1.219"/>
      <origin rpy="0 0 0" xyz="0.0 0.0 0.0"/>
      <inertia ixx="0.111172755531" ixy="0.0" ixz="0.0" iyy="0.111172755531" iyz="0.0" izz="0.21942"/>
    </inertial>
  </link>
  <joint name="l_wrist_3_joint" type="revolute">
    <parent link="l_wrist_2_link"/>
    <child link="l_wrist_3_link"/>
    <origin rpy="0.0 0.0 0.0" xyz="0.0 0.0 0.09465"/>
    <axis xyz="0 1 0"/>
    <limit effort="28.0" lower="-6.2831853" upper="6.2831853" velocity="3.2"/>
    <dynamics damping="0.0" friction="0.0"/>
  </joint>
  <link name="l_wrist_3_link">
    <visual>
      <geometry>
        <mesh filename="package://tom_description/meshes/arm/ur5/visual/Wrist3.dae"/>
      </geometry>
      <material name="LightGrey">
        <color rgba="0.7 0.7 0.7 1.0"/>
      </material>
    </visual>
    <collision>
      <geometry>
        <mesh filename="package://tom_description/meshes/arm/ur5/collision/wrist_3.stl"/>
      </geometry>
    </collision>
    <inertial>
      <mass value="0.1879"/>
      <origin rpy="0 0 0" xyz="0.0 0.0 0.0"/>
      <inertia ixx="0.0171364731454" ixy="0.0" ixz="0.0" iyy="0.0171364731454" iyz="0.0" izz="0.033822"/>
    </inertial>
  </link>
  <joint name="l_ee_fixed_joint" type="fixed">
    <parent link="l_wrist_3_link"/>
    <child link="l_ee_link"/>
    <origin rpy="0.0 0.0 1.570796325" xyz="0.0 0.0823 0.0"/>
  </joint>
  <link name="l_ee_link">
    <collision>
      <geometry>
        <box size="0.01 0.01 0.01"/>
      </geometry>
      <origin rpy="0 0 0" xyz="-0.01 0 0"/>
    </collision>
  </link>
  <transmission name="l_shoulder_pan_trans">
    <type>transmission_interface/SimpleTransmission</type>
    <joint name="l_shoulder_pan_joint">
      <hardwareInterface>EffortJointInterface</hardwareInterface>
    </joint>
    <actuator name="l_shoulder_pan_motor">
      <mechanicalReduction>1</mechanicalReduction>
    </actuator>
  </transmission>
  <transmission name="l_shoulder_lift_trans">
    <type>transmission_interface/SimpleTransmission</type>
    <joint name="l_shoulder_lift_joint">
      <hardwareInterface>EffortJointInterface</hardwareInterface>
    </joint>
    <actuator name="l_shoulder_lift_motor">
      <mechanicalReduction>1</mechanicalReduction>
    </actuator>
  </transmission>
  <transmission name="l_elbow_trans">
    <type>transmission_interface/SimpleTransmission</type>
    <joint name="l_elbow_joint">
      <hardwareInterface>EffortJointInterface</hardwareInterface>
    </joint>
    <actuator name="l_elbow_motor">
      <mechanicalReduction>1</mechanicalReduction>
    </actuator>
  </transmission>
  <transmission name="l_wrist_1_trans">
    <type>transmission_interface/SimpleTransmission</type>
    <joint name="l_wrist_1_joint">
      <hardwareInterface>EffortJointInterface</hardwareInterface>
    </joint>
    <actuator name="l_wrist_1_motor">
      <mechanicalReduction>1</mechanicalReduction>
    </actuator>
  </transmission>
  <transmission name="l_wrist_2_trans">
    <type>transmission_interface/SimpleTransmission</type>
    <joint name="l_wrist_2_joint">
      <hardwareInterface>EffortJointInterface</hardwareInterface>
    </joint>
    <actuator name="l_wrist_2_motor">
      <mechanicalReduction>1</mechanicalReduction>
    </actuator>
  </transmission>
  <transmission name="l_wrist_3_trans">
    <type>transmission_interface/SimpleTransmission</type>
    <joint name="l_wrist_3_joint">
      <hardwareInterface>EffortJointInterface</hardwareInterface>
    </joint>
    <actuator name="l_wrist_3_motor">
      <mechanicalReduction>1</mechanicalReduction>
    </actuator>
  </transmission>
  <!-- nothing to do here at the moment -->
  <joint name="torso_to_l_arm" type="fixed">
    <parent link="torso_link"/>
    <child link="l_base_link"/>
    <origin rpy="2.6061 0.6271 -2.6061" xyz="0 0.225 0"/>
  </joint>
  <!-- This is the JR3 adapter -->
  <link name="l_hand_base_adapter_link">
    <visual>
      <origin rpy="1.57079632679 0 1.57079632679" xyz="0 0 -0.045"/>
      <geometry>
        <mesh filename="package://tom_description/meshes/arm/hand_mount.dae"/>
      </geometry>
    </visual>
    <collision>
      <origin rpy="0 0 0" xyz="0 0 -0.025"/>
      <geometry>
        <cylinder length="0.05" radius="0.035"/>
      </geometry>
    </collision>
  </link>
  <joint name="l_hand_base_adapter_joint" type="fixed">
    <parent link="l_ee_link"/>
    <child link="l_hand_base_adapter_link"/>
    <origin rpy="1.57079632679 0.785 1.57079632679" xyz="0.045 0 0"/>
  </joint>
  <!-- Hands -->
  <!-- Right hand -->
  <!-- BASE -->
  <link name="r_hand_base_link">
    <visual>
      <geometry>
        <mesh filename="package://tom_description/meshes/hand/base_link.STL"/>
      </geometry>
      <origin rpy="0 0 0" xyz="0 0 0 "/>
       --&gt;

		
      <material name="black">
        <color rgba="0.2 0.2 0.2 1"/>
      </material>
    </visual>
    <collision>
      <origin rpy="0 0 0" xyz="-0.009300 0 -0.0475"/>
      <geometry>
        <box size="0.0408 0.1130 0.095"/>
      </geometry>
    </collision>
  </link>
  <!-- ============================================================================= -->
  <!-- FINGERS -->
  <!-- RIGHT HAND due to which finger is number 0 -->
  <!-- for LEFT HAND switch the sign of the **offset_origin_y** and **finger_angle_r** parameters-->
  <!-- [LINK 0, 4, 8] -->
  <link name="r_hand_link_index_0">
    <visual>
      <geometry>
        <mesh filename="package://tom_description/meshes/hand/link_0.0.STL"/>
      </geometry>
      <material name="black"/>
    </visual>
    <collision>
      <geometry>
        <box size="0.0196 0.0275 0.0164"/>
      </geometry>
      <origin rpy="0 0 0" xyz="0 0 0.0082"/>
    </collision>
  </link>
  <joint name="r_hand_joint_index_0" type="revolute">
    <axis xyz="0 0 1"/>
    <limit effort="0" lower="-0.47" upper="0.47" velocity="0"/>
    <parent link="r_hand_base_link"/>
    <child link="r_hand_link_index_0"/>
    <origin rpy="-0.08726646255 0 0" xyz="0 0.0435 -0.001542"/>
  </joint>
  <!-- [LINK 1, 5, 9] -->
  <link name="r_hand_link_index_1">
    <visual>
      <geometry>
        <mesh filename="package://tom_description/meshes/hand/link_1.0.STL"/>
      </geometry>
      <material name="black"/>
    </visual>
    <collision>
      <geometry>
        <box size="0.0196 0.0275 0.054"/>
      </geometry>
      <origin rpy="0 0 0" xyz="0 0 0.027"/>
    </collision>
  </link>
  <joint name="r_hand_joint_index_1" type="revolute">
    <limit effort="0" lower="-0.196" upper="1.61" velocity="0"/>
    <axis xyz="0 1 0"/>
    <parent link="r_hand_link_index_0"/>
    <child link="r_hand_link_index_1"/>
    <origin xyz="0 0 0.0164"/>
  </joint>
  <!-- [LINK 2, 6, 10]-->
  <link name="r_hand_link_index_2">
    <visual>
      <geometry>
        <mesh filename="package://tom_description/meshes/hand/link_2.0.STL"/>
      </geometry>
      <material name="black"/>
    </visual>
    <collision>
      <geometry>
        <box size="0.0196 0.0275 0.0384"/>
      </geometry>
      <origin rpy="0 0 0" xyz="0 0 0.0192"/>
    </collision>
  </link>
  <joint name="r_hand_joint_index_2" type="revolute">
    <axis xyz="0 1 0"/>
    <limit effort="0" lower="-0.174" upper="1.709" velocity="0"/>
    <parent link="r_hand_link_index_1"/>
    <child link="r_hand_link_index_2"/>
    <origin xyz="0 0 0.054"/>
  </joint>
  <!-- [LINK 3, 7, 11] -->
  <link name="r_hand_link_index_3">
    <visual>
      <geometry>
        <mesh filename="package://tom_description/meshes/hand/link_3.0.STL"/>
      </geometry>
      <material name="black"/>
    </visual>
    <collision>
      <geometry>
        <box size="0.0196 0.0275 0.0267"/>
      </geometry>
      <origin rpy="0 0 0" xyz="0 0 0.01335"/>
    </collision>
  </link>
  <joint name="r_hand_joint_index_3" type="revolute">
    <axis xyz="0 1 0"/>
    <limit effort="0" lower="-0.227" upper="1.618" velocity="0"/>
    <parent link="r_hand_link_index_2"/>
    <child link="r_hand_link_index_3"/>
    <origin xyz="0 0 0.0384"/>
  </joint>
  <!-- [FINGER TIP] -->
  <link name="r_hand_link_index_3_tip">
    <visual>
      <geometry>
        <mesh filename="package://tom_description/meshes/hand/link_3.0_tip.STL"/>
      </geometry>
      <material name="white">
        <color rgba=".9 .9 .9 1"/>
      </material>
    </visual>
    <collision>
      <geometry>
        <sphere radius="0.012"/>
      </geometry>
    </collision>
  </link>
  <joint name="r_hand_joint_index_3_tip" type="fixed">
    <parent link="r_hand_link_index_3"/>
    <child link="r_hand_link_index_3_tip"/>
    <origin rpy="0 0 0" xyz="0 0 0.0267"/>
  </joint>
  <!-- [LINK 0, 4, 8] -->
  <link name="r_hand_link_middle_0">
    <visual>
      <geometry>
        <mesh filename="package://tom_description/meshes/hand/link_0.0.STL"/>
      </geometry>
      <material name="black"/>
    </visual>
    <collision>
      <geometry>
        <box size="0.0196 0.0275 0.0164"/>
      </geometry>
      <origin rpy="0 0 0" xyz="0 0 0.0082"/>
    </collision>
  </link>
  <joint name="r_hand_joint_middle_0" type="revolute">
    <axis xyz="0 0 1"/>
    <limit effort="0" lower="-0.47" upper="0.47" velocity="0"/>
    <parent link="r_hand_base_link"/>
    <child link="r_hand_link_middle_0"/>
    <origin rpy="0.0 0 0" xyz="0 0 0.0007"/>
  </joint>
  <!-- [LINK 1, 5, 9] -->
  <link name="r_hand_link_middle_1">
    <visual>
      <geometry>
        <mesh filename="package://tom_description/meshes/hand/link_1.0.STL"/>
      </geometry>
      <material name="black"/>
    </visual>
    <collision>
      <geometry>
        <box size="0.0196 0.0275 0.054"/>
      </geometry>
      <origin rpy="0 0 0" xyz="0 0 0.027"/>
    </collision>
  </link>
  <joint name="r_hand_joint_middle_1" type="revolute">
    <limit effort="0" lower="-0.196" upper="1.61" velocity="0"/>
    <axis xyz="0 1 0"/>
    <parent link="r_hand_link_middle_0"/>
    <child link="r_hand_link_middle_1"/>
    <origin xyz="0 0 0.0164"/>
  </joint>
  <!-- [LINK 2, 6, 10]-->
  <link name="r_hand_link_middle_2">
    <visual>
      <geometry>
        <mesh filename="package://tom_description/meshes/hand/link_2.0.STL"/>
      </geometry>
      <material name="black"/>
    </visual>
    <collision>
      <geometry>
        <box size="0.0196 0.0275 0.0384"/>
      </geometry>
      <origin rpy="0 0 0" xyz="0 0 0.0192"/>
    </collision>
  </link>
  <joint name="r_hand_joint_middle_2" type="revolute">
    <axis xyz="0 1 0"/>
    <limit effort="0" lower="-0.174" upper="1.709" velocity="0"/>
    <parent link="r_hand_link_middle_1"/>
    <child link="r_hand_link_middle_2"/>
    <origin xyz="0 0 0.054"/>
  </joint>
  <!-- [LINK 3, 7, 11] -->
  <link name="r_hand_link_middle_3">
    <visual>
      <geometry>
        <mesh filename="package://tom_description/meshes/hand/link_3.0.STL"/>
      </geometry>
      <material name="black"/>
    </visual>
    <collision>
      <geometry>
        <box size="0.0196 0.0275 0.0267"/>
      </geometry>
      <origin rpy="0 0 0" xyz="0 0 0.01335"/>
    </collision>
  </link>
  <joint name="r_hand_joint_middle_3" type="revolute">
    <axis xyz="0 1 0"/>
    <limit effort="0" lower="-0.227" upper="1.618" velocity="0"/>
    <parent link="r_hand_link_middle_2"/>
    <child link="r_hand_link_middle_3"/>
    <origin xyz="0 0 0.0384"/>
  </joint>
  <!-- [FINGER TIP] -->
  <link name="r_hand_link_middle_3_tip">
    <visual>
      <geometry>
        <mesh filename="package://tom_description/meshes/hand/link_3.0_tip.STL"/>
      </geometry>
      <material name="white">
        <color rgba=".9 .9 .9 1"/>
      </material>
    </visual>
    <collision>
      <geometry>
        <sphere radius="0.012"/>
      </geometry>
    </collision>
  </link>
  <joint name="r_hand_joint_middle_3_tip" type="fixed">
    <parent link="r_hand_link_middle_3"/>
    <child link="r_hand_link_middle_3_tip"/>
    <origin rpy="0 0 0" xyz="0 0 0.0267"/>
  </joint>
  <!-- [LINK 0, 4, 8] -->
  <link name="r_hand_link_ring_0">
    <visual>
      <geometry>
        <mesh filename="package://tom_description/meshes/hand/link_0.0.STL"/>
      </geometry>
      <material name="black"/>
    </visual>
    <collision>
      <geometry>
        <box size="0.0196 0.0275 0.0164"/>
      </geometry>
      <origin rpy="0 0 0" xyz="0 0 0.0082"/>
    </collision>
  </link>
  <joint name="r_hand_joint_ring_0" type="revolute">
    <axis xyz="0 0 1"/>
    <limit effort="0" lower="-0.47" upper="0.47" velocity="0"/>
    <parent link="r_hand_base_link"/>
    <child link="r_hand_link_ring_0"/>
    <origin rpy="0.08726646255 0 0" xyz="0 -0.0435 -0.001542"/>
  </joint>
  <!-- [LINK 1, 5, 9] -->
  <link name="r_hand_link_ring_1">
    <visual>
      <geometry>
        <mesh filename="package://tom_description/meshes/hand/link_1.0.STL"/>
      </geometry>
      <material name="black"/>
    </visual>
    <collision>
      <geometry>
        <box size="0.0196 0.0275 0.054"/>
      </geometry>
      <origin rpy="0 0 0" xyz="0 0 0.027"/>
    </collision>
  </link>
  <joint name="r_hand_joint_ring_1" type="revolute">
    <limit effort="0" lower="-0.196" upper="1.61" velocity="0"/>
    <axis xyz="0 1 0"/>
    <parent link="r_hand_link_ring_0"/>
    <child link="r_hand_link_ring_1"/>
    <origin xyz="0 0 0.0164"/>
  </joint>
  <!-- [LINK 2, 6, 10]-->
  <link name="r_hand_link_ring_2">
    <visual>
      <geometry>
        <mesh filename="package://tom_description/meshes/hand/link_2.0.STL"/>
      </geometry>
      <material name="black"/>
    </visual>
    <collision>
      <geometry>
        <box size="0.0196 0.0275 0.0384"/>
      </geometry>
      <origin rpy="0 0 0" xyz="0 0 0.0192"/>
    </collision>
  </link>
  <joint name="r_hand_joint_ring_2" type="revolute">
    <axis xyz="0 1 0"/>
    <limit effort="0" lower="-0.174" upper="1.709" velocity="0"/>
    <parent link="r_hand_link_ring_1"/>
    <child link="r_hand_link_ring_2"/>
    <origin xyz="0 0 0.054"/>
  </joint>
  <!-- [LINK 3, 7, 11] -->
  <link name="r_hand_link_ring_3">
    <visual>
      <geometry>
        <mesh filename="package://tom_description/meshes/hand/link_3.0.STL"/>
      </geometry>
      <material name="black"/>
    </visual>
    <collision>
      <geometry>
        <box size="0.0196 0.0275 0.0267"/>
      </geometry>
      <origin rpy="0 0 0" xyz="0 0 0.01335"/>
    </collision>
  </link>
  <joint name="r_hand_joint_ring_3" type="revolute">
    <axis xyz="0 1 0"/>
    <limit effort="0" lower="-0.227" upper="1.618" velocity="0"/>
    <parent link="r_hand_link_ring_2"/>
    <child link="r_hand_link_ring_3"/>
    <origin xyz="0 0 0.0384"/>
  </joint>
  <!-- [FINGER TIP] -->
  <link name="r_hand_link_ring_3_tip">
    <visual>
      <geometry>
        <mesh filename="package://tom_description/meshes/hand/link_3.0_tip.STL"/>
      </geometry>
      <material name="white">
        <color rgba=".9 .9 .9 1"/>
      </material>
    </visual>
    <collision>
      <geometry>
        <sphere radius="0.012"/>
      </geometry>
    </collision>
  </link>
  <joint name="r_hand_joint_ring_3_tip" type="fixed">
    <parent link="r_hand_link_ring_3"/>
    <child link="r_hand_link_ring_3_tip"/>
    <origin rpy="0 0 0" xyz="0 0 0.0267"/>
  </joint>
  <!-- THUMB -->
  <!-- [LINK 12] -->
  <link name="r_hand_link_thumb_0">
    <visual>
      <geometry>
        <!-- RIGHT -->
        <mesh filename="package://tom_description/meshes/hand/link_12.0_right.STL"/>
        <!-- LEFT -->
        <!-- <mesh filename="package://tom_description/meshes/hand/link_12.0_left.STL" /> -->
      </geometry>
      <material name="black">
        <color rgba=".2 .2 .2 1"/>
      </material>
    </visual>
    <collision>
      <geometry>
        <box size="0.0358 0.034 0.0455"/>
      </geometry>
      <!-- RIGHT -->
      <origin rpy="0 0 0" xyz="-0.0179 0.009 0.0145"/>
      <!-- LEFT -->
      <!-- <origin rpy="0 0 0" xyz="${-0.0358/2+0.0} ${-.018/2} ${.029/2}"/> -->
    </collision>
  </link>
  <joint name="r_hand_joint_thumb_0" type="revolute">
    <axis xyz="-1 0 0"/>
    <limit effort="0" lower="0.263" upper="1.396" velocity="0"/>
    <parent link="r_hand_base_link"/>
    <child link="r_hand_link_thumb_0"/>
    <origin rpy="0 -1.65806278845 -1.5707963259" xyz="-0.0182 0.019333 -0.045987"/>
  </joint>
  <!-- [LINK 13] -->
  <link name="r_hand_link_thumb_1">
    <visual>
      <geometry>
        <mesh filename="package://tom_description/meshes/hand/link_13.0.STL"/>
      </geometry>
      <material name="black">
        <color rgba=".2 .2 .2 1"/>
      </material>
    </visual>
    <collision>
      <geometry>
        <box size="0.0196 0.0275 0.0177"/>
      </geometry>
      <origin rpy="0 0 0" xyz="0 0 0.00885"/>
    </collision>
  </link>
  <joint name="r_hand_joint_thumb_1" type="revolute">
    <axis xyz="0 0 1"/>
    <limit effort="0" lower="-0.105" upper="1.163" velocity="0"/>
    <parent link="r_hand_link_thumb_0"/>
    <child link="r_hand_link_thumb_1"/>
    <!-- RIGHT -->
    <origin xyz="-0.027 0.005 0.0399"/>
    <!-- LEFT -->
    <!-- <origin xyz="-0.027 -0.005 0.0399"/> -->
  </joint>
  <!-- [LINK 14] -->
  <link name="r_hand_link_thumb_2">
    <visual>
      <geometry>
        <mesh filename="package://tom_description/meshes/hand/link_14.0.STL"/>
      </geometry>
      <material name="black">
		  	</material>
    </visual>
    <collision>
      <geometry>
        <box size="0.0196 0.0275 0.0514"/>
      </geometry>
      <origin rpy="0 0 0" xyz="0 0 0.0257"/>
    </collision>
  </link>
  <joint name="r_hand_joint_thumb_2" type="revolute">
    <axis xyz="0 1 0"/>
    <limit effort="0" lower="-0.189" upper="1.644" velocity="0"/>
    <parent link="r_hand_link_thumb_1"/>
    <child link="r_hand_link_thumb_2"/>
    <origin xyz="0 0 0.0177"/>
  </joint>
  <!-- [LINK 15] -->
  <link name="r_hand_link_thumb_3">
    <visual>
      <geometry>
        <mesh filename="package://tom_description/meshes/hand/link_15.0.STL"/>
      </geometry>
      <material name="black">
    	</material>
    </visual>
    <collision>
      <geometry>
        <box size="0.0196 0.0275 0.0423"/>
      </geometry>
      <origin rpy="0 0 0" xyz="0 0 0.02115"/>
    </collision>
  </link>
  <joint name="r_hand_joint_thumb_3" type="revolute">
    <axis xyz="0 1 0"/>
    <limit effort="0" lower="-0.162" upper="1.719" velocity="0"/>
    <parent link="r_hand_link_thumb_2"/>
    <child link="r_hand_link_thumb_3"/>
    <origin xyz="0 0 0.0514"/>
  </joint>
  <!-- [FINGER TIP] -->
  <link name="r_hand_link_thumb_3_tip">
    <visual>
      <geometry>
        <mesh filename="package://tom_description/meshes/hand/link_15.0_tip.STL"/>
      </geometry>
      <material name="white">
        <color rgba=".9 .9 .9 1"/>
      </material>
    </visual>
    <collision>
      <geometry>
        <sphere radius="0.012"/>
      </geometry>
      <origin rpy="0 0 0" xyz="0 0 0"/>
    </collision>
  </link>
  <joint name="r_hand_joint_thumb_3_tip" type="fixed">
    <parent link="r_hand_link_thumb_3"/>
    <child link="r_hand_link_thumb_3_tip"/>
    <origin rpy="0 0 0" xyz="0 0 0.0423"/>
    <!--0.0267000000000005-->
  </joint>
  <joint name="r_hand_base_joint" type="fixed">
    <parent link="r_hand_base_adapter_link"/>
    <child link="r_hand_base_link"/>
    <origin rpy="0 0 0" xyz="0.01 0 0.095"/>
  </joint>
  <!-- Left Hand -->
  <!-- BASE -->
  <link name="l_hand_base_link">
    <visual>
      <geometry>
        <mesh filename="package://tom_description/meshes/hand/base_link_left.STL"/>
      </geometry>
      <!-- LEFT -->
      <origin rpy="-1.5707963259 0 0" xyz="0 0 0 "/>
      <!-- RIGHT -->
      <!--<origin rpy="0 0 0" xyz="0 0 0 "/>-->
      <material name="black">
        <color rgba="0.2 0.2 0.2 1"/>
      </material>
    </visual>
    <collision>
      <origin rpy="0 0 0" xyz="-0.009300 0 -0.0475"/>
      <geometry>
        <box size="0.0408 0.1130 0.095"/>
      </geometry>
    </collision>
  </link>
  <!-- ============================================================================= -->
  <!-- FINGERS -->
  <!-- RIGHT HAND due to which finger is number 0 -->
  <!-- for LEFT HAND switch the sign of the **offset_origin_y** and **finger_angle_r** parameters-->
  <!-- [LINK 0, 4, 8] -->
  <link name="l_hand_link_ring_0">
    <visual>
      <geometry>
        <mesh filename="package://tom_description/meshes/hand/link_0.0.STL"/>
      </geometry>
      <material name="black"/>
    </visual>
    <collision>
      <geometry>
        <box size="0.0196 0.0275 0.0164"/>
      </geometry>
      <origin rpy="0 0 0" xyz="0 0 0.0082"/>
    </collision>
  </link>
  <joint name="l_hand_joint_ring_0" type="revolute">
    <axis xyz="0 0 1"/>
    <limit effort="0" lower="-0.47" upper="0.47" velocity="0"/>
    <parent link="l_hand_base_link"/>
    <child link="l_hand_link_ring_0"/>
    <origin rpy="-0.08726646255 0 0" xyz="0 0.0435 -0.001542"/>
  </joint>
  <!-- [LINK 1, 5, 9] -->
  <link name="l_hand_link_ring_1">
    <visual>
      <geometry>
        <mesh filename="package://tom_description/meshes/hand/link_1.0.STL"/>
      </geometry>
      <material name="black"/>
    </visual>
    <collision>
      <geometry>
        <box size="0.0196 0.0275 0.054"/>
      </geometry>
      <origin rpy="0 0 0" xyz="0 0 0.027"/>
    </collision>
  </link>
  <joint name="l_hand_joint_ring_1" type="revolute">
    <limit effort="0" lower="-0.196" upper="1.61" velocity="0"/>
    <axis xyz="0 1 0"/>
    <parent link="l_hand_link_ring_0"/>
    <child link="l_hand_link_ring_1"/>
    <origin xyz="0 0 0.0164"/>
  </joint>
  <!-- [LINK 2, 6, 10]-->
  <link name="l_hand_link_ring_2">
    <visual>
      <geometry>
        <mesh filename="package://tom_description/meshes/hand/link_2.0.STL"/>
      </geometry>
      <material name="black"/>
    </visual>
    <collision>
      <geometry>
        <box size="0.0196 0.0275 0.0384"/>
      </geometry>
      <origin rpy="0 0 0" xyz="0 0 0.0192"/>
    </collision>
  </link>
  <joint name="l_hand_joint_ring_2" type="revolute">
    <axis xyz="0 1 0"/>
    <limit effort="0" lower="-0.174" upper="1.709" velocity="0"/>
    <parent link="l_hand_link_ring_1"/>
    <child link="l_hand_link_ring_2"/>
    <origin xyz="0 0 0.054"/>
  </joint>
  <!-- [LINK 3, 7, 11] -->
  <link name="l_hand_link_ring_3">
    <visual>
      <geometry>
        <mesh filename="package://tom_description/meshes/hand/link_3.0.STL"/>
      </geometry>
      <material name="black"/>
    </visual>
    <collision>
      <geometry>
        <box size="0.0196 0.0275 0.0267"/>
      </geometry>
      <origin rpy="0 0 0" xyz="0 0 0.01335"/>
    </collision>
  </link>
  <joint name="l_hand_joint_ring_3" type="revolute">
    <axis xyz="0 1 0"/>
    <limit effort="0" lower="-0.227" upper="1.618" velocity="0"/>
    <parent link="l_hand_link_ring_2"/>
    <child link="l_hand_link_ring_3"/>
    <origin xyz="0 0 0.0384"/>
  </joint>
  <!-- [FINGER TIP] -->
  <link name="l_hand_link_ring_3_tip">
    <visual>
      <geometry>
        <mesh filename="package://tom_description/meshes/hand/link_3.0_tip.STL"/>
      </geometry>
      <material name="white">
        <color rgba=".9 .9 .9 1"/>
      </material>
    </visual>
    <collision>
      <geometry>
        <sphere radius="0.012"/>
      </geometry>
    </collision>
  </link>
  <joint name="l_hand_joint_ring_3_tip" type="fixed">
    <parent link="l_hand_link_ring_3"/>
    <child link="l_hand_link_ring_3_tip"/>
    <origin rpy="0 0 0" xyz="0 0 0.0267"/>
  </joint>
  <!-- [LINK 0, 4, 8] -->
  <link name="l_hand_link_middle_0">
    <visual>
      <geometry>
        <mesh filename="package://tom_description/meshes/hand/link_0.0.STL"/>
      </geometry>
      <material name="black"/>
    </visual>
    <collision>
      <geometry>
        <box size="0.0196 0.0275 0.0164"/>
      </geometry>
      <origin rpy="0 0 0" xyz="0 0 0.0082"/>
    </collision>
  </link>
  <joint name="l_hand_joint_middle_0" type="revolute">
    <axis xyz="0 0 1"/>
    <limit effort="0" lower="-0.47" upper="0.47" velocity="0"/>
    <parent link="l_hand_base_link"/>
    <child link="l_hand_link_middle_0"/>
    <origin rpy="0.0 0 0" xyz="0 0 0.0007"/>
  </joint>
  <!-- [LINK 1, 5, 9] -->
  <link name="l_hand_link_middle_1">
    <visual>
      <geometry>
        <mesh filename="package://tom_description/meshes/hand/link_1.0.STL"/>
      </geometry>
      <material name="black"/>
    </visual>
    <collision>
      <geometry>
        <box size="0.0196 0.0275 0.054"/>
      </geometry>
      <origin rpy="0 0 0" xyz="0 0 0.027"/>
    </collision>
  </link>
  <joint name="l_hand_joint_middle_1" type="revolute">
    <limit effort="0" lower="-0.196" upper="1.61" velocity="0"/>
    <axis xyz="0 1 0"/>
    <parent link="l_hand_link_middle_0"/>
    <child link="l_hand_link_middle_1"/>
    <origin xyz="0 0 0.0164"/>
  </joint>
  <!-- [LINK 2, 6, 10]-->
  <link name="l_hand_link_middle_2">
    <visual>
      <geometry>
        <mesh filename="package://tom_description/meshes/hand/link_2.0.STL"/>
      </geometry>
      <material name="black"/>
    </visual>
    <collision>
      <geometry>
        <box size="0.0196 0.0275 0.0384"/>
      </geometry>
      <origin rpy="0 0 0" xyz="0 0 0.0192"/>
    </collision>
  </link>
  <joint name="l_hand_joint_middle_2" type="revolute">
    <axis xyz="0 1 0"/>
    <limit effort="0" lower="-0.174" upper="1.709" velocity="0"/>
    <parent link="l_hand_link_middle_1"/>
    <child link="l_hand_link_middle_2"/>
    <origin xyz="0 0 0.054"/>
  </joint>
  <!-- [LINK 3, 7, 11] -->
  <link name="l_hand_link_middle_3">
    <visual>
      <geometry>
        <mesh filename="package://tom_description/meshes/hand/link_3.0.STL"/>
      </geometry>
      <material name="black"/>
    </visual>
    <collision>
      <geometry>
        <box size="0.0196 0.0275 0.0267"/>
      </geometry>
      <origin rpy="0 0 0" xyz="0 0 0.01335"/>
    </collision>
  </link>
  <joint name="l_hand_joint_middle_3" type="revolute">
    <axis xyz="0 1 0"/>
    <limit effort="0" lower="-0.227" upper="1.618" velocity="0"/>
    <parent link="l_hand_link_middle_2"/>
    <child link="l_hand_link_middle_3"/>
    <origin xyz="0 0 0.0384"/>
  </joint>
  <!-- [FINGER TIP] -->
  <link name="l_hand_link_middle_3_tip">
    <visual>
      <geometry>
        <mesh filename="package://tom_description/meshes/hand/link_3.0_tip.STL"/>
      </geometry>
      <material name="white">
        <color rgba=".9 .9 .9 1"/>
      </material>
    </visual>
    <collision>
      <geometry>
        <sphere radius="0.012"/>
      </geometry>
    </collision>
  </link>
  <joint name="l_hand_joint_middle_3_tip" type="fixed">
    <parent link="l_hand_link_middle_3"/>
    <child link="l_hand_link_middle_3_tip"/>
    <origin rpy="0 0 0" xyz="0 0 0.0267"/>
  </joint>
  <!-- [LINK 0, 4, 8] -->
  <link name="l_hand_link_index_0">
    <visual>
      <geometry>
        <mesh filename="package://tom_description/meshes/hand/link_0.0.STL"/>
      </geometry>
      <material name="black"/>
    </visual>
    <collision>
      <geometry>
        <box size="0.0196 0.0275 0.0164"/>
      </geometry>
      <origin rpy="0 0 0" xyz="0 0 0.0082"/>
    </collision>
  </link>
  <joint name="l_hand_joint_index_0" type="revolute">
    <axis xyz="0 0 1"/>
    <limit effort="0" lower="-0.47" upper="0.47" velocity="0"/>
    <parent link="l_hand_base_link"/>
    <child link="l_hand_link_index_0"/>
    <origin rpy="0.08726646255 0 0" xyz="0 -0.0435 -0.001542"/>
  </joint>
  <!-- [LINK 1, 5, 9] -->
  <link name="l_hand_link_index_1">
    <visual>
      <geometry>
        <mesh filename="package://tom_description/meshes/hand/link_1.0.STL"/>
      </geometry>
      <material name="black"/>
    </visual>
    <collision>
      <geometry>
        <box size="0.0196 0.0275 0.054"/>
      </geometry>
      <origin rpy="0 0 0" xyz="0 0 0.027"/>
    </collision>
  </link>
  <joint name="l_hand_joint_index_1" type="revolute">
    <limit effort="0" lower="-0.196" upper="1.61" velocity="0"/>
    <axis xyz="0 1 0"/>
    <parent link="l_hand_link_index_0"/>
    <child link="l_hand_link_index_1"/>
    <origin xyz="0 0 0.0164"/>
  </joint>
  <!-- [LINK 2, 6, 10]-->
  <link name="l_hand_link_index_2">
    <visual>
      <geometry>
        <mesh filename="package://tom_description/meshes/hand/link_2.0.STL"/>
      </geometry>
      <material name="black"/>
    </visual>
    <collision>
      <geometry>
        <box size="0.0196 0.0275 0.0384"/>
      </geometry>
      <origin rpy="0 0 0" xyz="0 0 0.0192"/>
    </collision>
  </link>
  <joint name="l_hand_joint_index_2" type="revolute">
    <axis xyz="0 1 0"/>
    <limit effort="0" lower="-0.174" upper="1.709" velocity="0"/>
    <parent link="l_hand_link_index_1"/>
    <child link="l_hand_link_index_2"/>
    <origin xyz="0 0 0.054"/>
  </joint>
  <!-- [LINK 3, 7, 11] -->
  <link name="l_hand_link_index_3">
    <visual>
      <geometry>
        <mesh filename="package://tom_description/meshes/hand/link_3.0.STL"/>
      </geometry>
      <material name="black"/>
    </visual>
    <collision>
      <geometry>
        <box size="0.0196 0.0275 0.0267"/>
      </geometry>
      <origin rpy="0 0 0" xyz="0 0 0.01335"/>
    </collision>
  </link>
  <joint name="l_hand_joint_index_3" type="revolute">
    <axis xyz="0 1 0"/>
    <limit effort="0" lower="-0.227" upper="1.618" velocity="0"/>
    <parent link="l_hand_link_index_2"/>
    <child link="l_hand_link_index_3"/>
    <origin xyz="0 0 0.0384"/>
  </joint>
  <!-- [FINGER TIP] -->
  <link name="l_hand_link_index_3_tip">
    <visual>
      <geometry>
        <mesh filename="package://tom_description/meshes/hand/link_3.0_tip.STL"/>
      </geometry>
      <material name="white">
        <color rgba=".9 .9 .9 1"/>
      </material>
    </visual>
    <collision>
      <geometry>
        <sphere radius="0.012"/>
      </geometry>
    </collision>
  </link>
  <joint name="l_hand_joint_index_3_tip" type="fixed">
    <parent link="l_hand_link_index_3"/>
    <child link="l_hand_link_index_3_tip"/>
    <origin rpy="0 0 0" xyz="0 0 0.0267"/>
  </joint>
  <!-- THUMB -->
  <!-- [LINK 12] -->
  <link name="l_hand_link_thumb_0">
    <visual>
      <geometry>
        <mesh filename="package://tom_description/meshes/hand/link_12.0_left.STL"/>
      </geometry>
      <material name="black">
        <color rgba=".2 .2 .2 1"/>
      </material>
      <origin rpy="3.1415926518 0 0" xyz="0 0 0"/>
    </visual>
    <collision>
      <geometry>
        <box size="0.0358 0.034 0.0455"/>
      </geometry>
      <origin rpy="0 0 0" xyz="-0.0179 -0.009 0.0145"/>
    </collision>
  </link>
  <joint name="l_hand_joint_thumb_0" type="revolute">
    <axis xyz="+1 0 0"/>
    <limit effort="0" lower="0.263" upper="1.396" velocity="0"/>
    <parent link="l_hand_base_link"/>
    <child link="l_hand_link_thumb_0"/>
    <origin rpy="0 -1.65806278845 1.5707963259" xyz="-0.0182 -0.019333 -0.045987"/>
  </joint>
  <!-- [LINK 13] -->
  <link name="l_hand_link_thumb_1">
    <visual>
      <geometry>
        <mesh filename="package://tom_description/meshes/hand/link_13.0.STL"/>
      </geometry>
      <material name="black">
        <color rgba=".2 .2 .2 1"/>
      </material>
    </visual>
    <collision>
      <geometry>
        <box size="0.0196 0.0275 0.0177"/>
      </geometry>
      <origin rpy="0 0 0" xyz="0 0 0.00885"/>
    </collision>
  </link>
  <joint name="l_hand_joint_thumb_1" type="revolute">
    <axis xyz="0 0 -1"/>
    <limit effort="0" lower="-0.105" upper="1.163" velocity="0"/>
    <parent link="l_hand_link_thumb_0"/>
    <child link="l_hand_link_thumb_1"/>
    <!-- RIGHT -->
    <!-- <origin xyz="-0.027 0.005 0.0399"/> -->
    <!-- LEFT -->
    <origin xyz="-0.027 -0.005 0.0399"/>
  </joint>
  <!-- [LINK 14] -->
  <link name="l_hand_link_thumb_2">
    <visual>
      <geometry>
        <mesh filename="package://tom_description/meshes/hand/link_14.0.STL"/>
      </geometry>
      <material name="black">
		  	</material>
    </visual>
    <collision>
      <geometry>
        <box size="0.0196 0.0275 0.0514"/>
      </geometry>
      <origin rpy="0 0 0" xyz="0 0 0.0257"/>
    </collision>
  </link>
  <joint name="l_hand_joint_thumb_2" type="revolute">
    <axis xyz="0 1 0"/>
    <limit effort="0" lower="-0.189" upper="1.644" velocity="0"/>
    <parent link="l_hand_link_thumb_1"/>
    <child link="l_hand_link_thumb_2"/>
    <origin xyz="0 0 0.0177"/>
  </joint>
  <!-- [LINK 15] -->
  <link name="l_hand_link_thumb_3">
    <visual>
      <geometry>
        <mesh filename="package://tom_description/meshes/hand/link_15.0.STL"/>
      </geometry>
      <material name="black">
    	</material>
    </visual>
    <collision>
      <geometry>
        <box size="0.0196 0.0275 0.0423"/>
      </geometry>
      <origin rpy="0 0 0" xyz="0 0 0.02115"/>
    </collision>
  </link>
  <joint name="l_hand_joint_thumb_3" type="revolute">
    <axis xyz="0 1 0"/>
    <limit effort="0" lower="-0.162" upper="1.719" velocity="0"/>
    <parent link="l_hand_link_thumb_2"/>
    <child link="l_hand_link_thumb_3"/>
    <origin xyz="0 0 0.0514"/>
  </joint>
  <!-- [FINGER TIP] -->
  <link name="l_hand_link_thumb_3_tip">
    <visual>
      <geometry>
        <mesh filename="package://tom_description/meshes/hand/link_15.0_tip.STL"/>
      </geometry>
      <material name="white">
        <color rgba=".9 .9 .9 1"/>
      </material>
    </visual>
    <collision>
      <geometry>
        <sphere radius="0.012"/>
      </geometry>
      <origin rpy="0 0 0" xyz="0 0 0"/>
    </collision>
  </link>
  <joint name="l_hand_joint_thumb_3_tip" type="fixed">
    <parent link="l_hand_link_thumb_3"/>
    <child link="l_hand_link_thumb_3_tip"/>
    <origin rpy="0 0 0" xyz="0 0 0.0423"/>
    <!--0.0267000000000005-->
  </joint>
  <joint name="l_hand_base_joint" type="fixed">
    <parent link="l_hand_base_adapter_link"/>
    <child link="l_hand_base_link"/>
    <origin rpy="0 0 0" xyz="0.01 0 0.095"/>
  </joint>
  <!-- Sensors -->
  <!-- Sensors -->
  <link name="front_laser_scanner_link">
    <visual>
      <origin rpy="0 0 0" xyz="0 0 0"/>
      <geometry>
        <cylinder length="0.05" radius="0.02"/>
      </geometry>
      <material name="light_grey">
        <color rgba="0.5 0.5 0.5 1"/>
      </material>
    </visual>
    <collision>
      <origin rpy="0 0 0" xyz="0 0 0"/>
      <geometry>
        <cylinder length="0.05" radius="0.02"/>
      </geometry>
    </collision>
  </link>
  <joint name="front_laser_scanner" type="fixed">
    <parent link="base_link"/>
    <child link="front_laser_scanner_link"/>
    <!-- <origin xyz="0.01464 0.26511 -0.22" rpy="3.14 0 0.7535"/> -->
    <origin rpy="3.14 0 0.785" xyz="0.01464 0.26511 -0.22"/>
  </joint>
  <link name="rear_laser_scanner_link">
    <visual>
      <origin rpy="0 0 0" xyz="0 0 0"/>
      <geometry>
        <cylinder length="0.05" radius="0.02"/>
      </geometry>
      <material name="light_grey"/>
    </visual>
    <collision>
      <origin rpy="0 0 0" xyz="0 0 0"/>
      <geometry>
        <cylinder length="0.05" radius="0.02"/>
      </geometry>
    </collision>
  </link>
  <joint name="rear_laser_scanner" type="fixed">
    <parent link="base_link"/>
    <child link="rear_laser_scanner_link"/>
    <!-- <origin xyz="-0.86614 -0.26415 -0.22" rpy="3.14 0 -2.3235"/> -->
    <origin rpy="3.14 0 -2.355" xyz="-0.86614 -0.26415 -0.22"/>
  </joint>
</robot>

